<mujoco model="stiff-rope">
  <compiler angle="radian" />

  <extension>
    <plugin plugin="mujoco.elasticity.cable">
      <instance name="composite">
        <config key="twist" value="9921837.044899195" />
        <config key="bend" value="3382730.2472470007" />
      </instance>
    </plugin>
  </extension>

  <custom>
    <text name="composite_" data="rope_" />
  </custom>

  <worldbody>
    <body name="stiffrope" pos="6.5 0 0.5" quat="0 0 1 0">
      <joint name="freejoint_A" type="free" limited="false" actuatorfrclimited="false" />
      <body name="B_first">
        <geom name="G0" size="0.015 0.5" pos="0.5 0 0" quat="0.707107 0 -0.707107 0" type="capsule" contype="0" conaffinity="0" condim="1" solref="0.001" mass="0.0769231" rgba="0.1 0.0533333 0.673333 1" />
        <site name="S_first" pos="0 0 0" group="3" />
        <plugin instance="composite" />
        <body name="B_1" pos="1 0 0">
          <joint name="J_1" pos="0 0 0" type="ball" group="3" actuatorfrclimited="false" damping="0.5" />
          <geom name="G1" size="0.015 0.5" pos="0.5 0 0" quat="0.707107 0 -0.707107 0" type="capsule" contype="0" conaffinity="0" condim="1" solref="0.001" mass="0.0769231" rgba="0.1 0.0533333 0.673333 1" />
          <plugin instance="composite" />
          <body name="B_2" pos="1 0 0">
            <joint name="J_2" pos="0 0 0" type="ball" group="3" actuatorfrclimited="false" damping="0.5" />
            <geom name="G2" size="0.015 0.5" pos="0.5 0 0" quat="0.707107 0 -0.707107 0" type="capsule" contype="0" conaffinity="0" condim="1" solref="0.001" mass="0.0769231" rgba="0.1 0.0533333 0.673333 1" />
            <plugin instance="composite" />
            <body name="B_3" pos="1 0 0">
              <joint name="J_3" pos="0 0 0" type="ball" group="3" actuatorfrclimited="false" damping="0.5" />
              <geom name="G3" size="0.015 0.5" pos="0.5 0 0" quat="0.707107 0 -0.707107 0" type="capsule" contype="0" conaffinity="0" condim="1" solref="0.001" mass="0.0769231" rgba="0.1 0.0533333 0.673333 1" />
              <plugin instance="composite" />
              <body name="B_4" pos="1 0 0">
                <joint name="J_4" pos="0 0 0" type="ball" group="3" actuatorfrclimited="false" damping="0.5" />
                <geom name="G4" size="0.015 0.5" pos="0.5 0 0" quat="0.707107 0 -0.707107 0" type="capsule" contype="0" conaffinity="0" condim="1" solref="0.001" mass="0.0769231" rgba="0.1 0.0533333 0.673333 1" />
                <plugin instance="composite" />
                <body name="B_5" pos="1 0 0">
                  <joint name="J_5" pos="0 0 0" type="ball" group="3" actuatorfrclimited="false" damping="0.5" />
                  <geom name="G5" size="0.015 0.5" pos="0.5 0 0" quat="0.707107 0 -0.707107 0" type="capsule" contype="0" conaffinity="0" condim="1" solref="0.001" mass="0.0769231" rgba="0.1 0.0533333 0.673333 1" />
                  <plugin instance="composite" />
                  <body name="B_6" pos="1 0 0">
                    <joint name="J_6" pos="0 0 0" type="ball" group="3" actuatorfrclimited="false" damping="0.5" />
                    <geom name="G6" size="0.015 0.5" pos="0.5 0 0" quat="0.707107 0 -0.707107 0" type="capsule" contype="0" conaffinity="0" condim="1" solref="0.001" mass="0.0769231" rgba="0.1 0.0533333 0.673333 1" />
                    <plugin instance="composite" />
                    <body name="B_7" pos="1 0 0">
                      <joint name="J_7" pos="0 0 0" type="ball" group="3" actuatorfrclimited="false" damping="0.5" />
                      <geom name="G7" size="0.015 0.5" pos="0.5 0 0" quat="0.707107 0 -0.707107 0" type="capsule" contype="0" conaffinity="0" condim="1" solref="0.001" mass="0.0769231" rgba="0.1 0.0533333 0.673333 1" />
                      <plugin instance="composite" />
                      <body name="B_8" pos="1 0 0">
                        <site name="S_8" pos="1 0 0" group="3"/>
<joint name="J_8" pos="0 0 0" type="ball" group="3" actuatorfrclimited="false" damping="0.5" />
                        <geom name="G8" size="0.015 0.5" pos="0.5 0 0" quat="0.707107 0 -0.707107 0" type="capsule" contype="0" conaffinity="0" condim="1" solref="0.001" mass="0.0769231" rgba="0.1 0.0533333 0.673333 1" />
                        <plugin instance="composite" />
                        <body name="B_9" pos="1 0 0">
                          <joint name="J_9" pos="0 0 0" type="ball" group="3" actuatorfrclimited="false" damping="0.5" />
                          <geom name="G9" size="0.015 0.5" pos="0.5 0 0" quat="0.707107 0 -0.707107 0" type="capsule" contype="0" conaffinity="0" condim="1" solref="0.001" mass="0.0769231" rgba="0.1 0.0533333 0.673333 1" />
                          <plugin instance="composite" />
                          <body name="B_10" pos="1 0 0">
                            <site name="S_10" pos="1 0 0" group="3" />
<joint name="J_10" pos="0 0 0" type="ball" group="3" actuatorfrclimited="false" damping="0.5" />
                            <geom name="G10" size="0.015 0.5" pos="0.5 0 0" quat="0.707107 0 -0.707107 0" type="capsule" contype="0" conaffinity="0" condim="1" solref="0.001" mass="0.0769231" rgba="0.1 0.0533333 0.673333 1" />
                            <plugin instance="composite" />
                            <body name="B_11" pos="1 0 0">
                              <joint name="J_11" pos="0 0 0" type="ball" group="3" actuatorfrclimited="false" damping="0.5" />
                              <geom name="G11" size="0.015 0.5" pos="0.5 0 0" quat="0.707107 0 -0.707107 0" type="capsule" contype="0" conaffinity="0" condim="1" solref="0.001" mass="0.0769231" rgba="0.1 0.0533333 0.673333 1" />
                              <plugin instance="composite" />
                              <body name="B_last" pos="1 0 0">
                                <body name="B_last2" pos="1 0 0" />
<joint name="J_last" pos="0 0 0" type="ball" group="3" actuatorfrclimited="false" damping="0.5" />
                                <geom name="G12" size="0.015 0.5" pos="0.5 0 0" quat="0.707107 0 -0.707107 0" type="capsule" contype="0" conaffinity="0" condim="1" solref="0.001" mass="0.0769231" rgba="0.1 0.0533333 0.673333 1" />
                                <site name="S_last" pos="1 0 0" group="3" />
                                <plugin instance="composite" />
                              </body>
                            </body>
                          </body>
                        </body>
                      </body>
                    </body>
                  </body>
                </body>
              </body>
            </body>
          </body>
        </body>
      </body>
    </body>
  </worldbody>

  <contact>
    <exclude body1="B_first" body2="B_1" />
    <exclude body1="B_1" body2="B_2" />
    <exclude body1="B_2" body2="B_3" />
    <exclude body1="B_3" body2="B_4" />
    <exclude body1="B_4" body2="B_5" />
    <exclude body1="B_5" body2="B_6" />
    <exclude body1="B_6" body2="B_7" />
    <exclude body1="B_7" body2="B_8" />
    <exclude body1="B_8" body2="B_9" />
    <exclude body1="B_9" body2="B_10" />
    <exclude body1="B_10" body2="B_11" />
    <exclude body1="B_11" body2="B_last" />
  </contact>
</mujoco>