<mujoco model="base">
  <compiler angle="radian"/>

  <option timestep="0.0015" tolerance="1e-10" integrator="implicit" cone="elliptic" jacobian="sparse" iterations="30"/>

  <size njmax="5000" nconmax="5000"/>

  <visual>
    <quality shadowsize="2048"/>
    <map stiffness="700" fogstart="10" fogend="15" znear="0.001" zfar="40" shadowscale="0.5"/>
    <rgba haze="0.15 0.25 0.35 1"/>
  </visual>

  <statistic meansize="0.05" extent="2"/>

  <asset>
    <texture type="skybox" builtin="gradient" rgb1="1 1 0.9" rgb2="0.9 0.9 0.81" width="512" height="3072"/>
    <texture type="2d" name="texplane" builtin="checker" mark="cross" rgb1="0.2 0.3 0.4" rgb2="0.1 0.15 0.2" markrgb="0.8 0.8 0.8" width="512" height="512"/>
    <material name="matplane" texture="texplane" texuniform="true" reflectance="0.3"/>
  </asset>

  <worldbody>
    <geom name="floor" size="3 3 0.125" pos="0 0 -10" type="plane" condim="1" material="matplane"/>
    <camera pos="0 -1 1.5" quat="0.866019 0.500011 0 0"/>
    <camera pos="1 -1.2 0.8" quat="0.687095 0.527073 0.304042 0.397055"/>
    <camera pos="-1.8 -1.1 0.7" quat="0.732963 0.562422 -0.232963 -0.303603"/>
    <camera pos="-1 -1.5 0.5" quat="0.707107 0.707107 0 0"/>
    <camera pos="9.7 -1 1.1" quat="0.687095 0.527073 0.304042 0.397055"/>
    <camera pos="4.5 -8 0.5" quat="0.707107 0.707107 0 0"/>
    <light pos="0 0 5" dir="0 0 -1" directional="true" castshadow="false" diffuse="0.4 0.4 0.4" specular="0.1 0.1 0.1"/>
    <light pos="0 0 4" dir="0 0 -1" directional="true" diffuse="0.6 0.6 0.6" specular="0.2 0.2 0.2"/>
    <body name="eef_body" pos="-6.5 0 0.5">
      <geom name="eef_geom" size="0.03 0.03 0.06" type="box" contype="0" conaffinity="0" mass="1" rgba="0.8 0.2 0.1 0"/>
    </body>
    <body name="eef_body2" pos="6.5 0 0.5">
      <geom name="eef_geom2" size="0.03 0.03 0.06" type="box" contype="0" conaffinity="0" mass="1" rgba="0.8 0.2 0.1 0"/>
    </body>
    <body name="stiffrope" pos="6.5 0 0.5" quat="0 0 1 0">
      <joint name="freejoint_A" type="free" limited="false" actuatorfrclimited="false"/>
      <site name="ft_rope" pos="0 0 0" size="0.03" group="1" rgba="1 0 0 0"/>
      <body name="Bmain_first">
        <geom name="G0" size="0.015 0.5" pos="0.5 0 0" quat="0.707107 0 -0.707107 0" type="capsule" contype="0" conaffinity="0" condim="1" solref="0.001" rgba="0.1 0.0533333 0.673333 1"/>
        <site name="S_first" pos="0 0 0" size="0.0135"/>
        <site name="S_0" pos="0 0 0" size="0.0135" rgba="0 0 0 0"/>
        <site name="twistcylx_1" pos="0 0 0.05" quat="0.707107 0 0 -0.707107" size="0.001 0.05" group="1" type="cylinder" rgba="0 0 1 0"/>
        <site name="twistcyly_1" pos="0 0.05 0" quat="0.707107 -0.707107 0 0" size="0.001 0.05" group="1" type="cylinder" rgba="1 1 0 0"/>
        <body name="B_first">
          <geom size="0.0135" contype="0" conaffinity="0" mass="0" rgba="0.8 0.2 0.1 0.3"/>
        </body>
        <body name="Bmain_1" pos="1 0 0">
          <joint name="J_1" pos="0 0 0" type="ball" actuatorfrclimited="false" damping="0.5"/>
          <geom name="G1" size="0.015 0.5" pos="0.5 0 0" quat="0.707107 0 -0.707107 0" type="capsule" contype="0" conaffinity="0" condim="1" solref="0.001" rgba="0.1 0.0533333 0.673333 1"/>
          <site name="S_1" pos="0 0 0" size="0.0135" rgba="0 0 0 0"/>
          <body name="B_1">
            <geom size="0.0135" contype="0" conaffinity="0" mass="0" rgba="0.8 0.2 0.1 0.3"/>
          </body>
          <body name="Bmain_2" pos="1 0 0">
            <joint name="J_2" pos="0 0 0" type="ball" actuatorfrclimited="false" damping="0.5"/>
            <geom name="G2" size="0.015 0.5" pos="0.5 0 0" quat="0.707107 0 -0.707107 0" type="capsule" contype="0" conaffinity="0" condim="1" solref="0.001" rgba="0.1 0.0533333 0.673333 1"/>
            <site name="S_2" pos="0 0 0" size="0.0135" rgba="0 0 0 0"/>
            <body name="B_2">
              <geom size="0.0135" contype="0" conaffinity="0" mass="0" rgba="0.8 0.2 0.1 0.3"/>
            </body>
            <body name="Bmain_3" pos="1 0 0">
              <joint name="J_3" pos="0 0 0" type="ball" actuatorfrclimited="false" damping="0.5"/>
              <geom name="G3" size="0.015 0.5" pos="0.5 0 0" quat="0.707107 0 -0.707107 0" type="capsule" contype="0" conaffinity="0" condim="1" solref="0.001" rgba="0.1 0.0533333 0.673333 1"/>
              <site name="S_3" pos="0 0 0" size="0.0135" rgba="0 0 0 0"/>
              <body name="B_3">
                <geom size="0.0135" contype="0" conaffinity="0" mass="0" rgba="0.8 0.2 0.1 0.3"/>
              </body>
              <body name="Bmain_4" pos="1 0 0">
                <joint name="J_4" pos="0 0 0" type="ball" actuatorfrclimited="false" damping="0.5"/>
                <geom name="G4" size="0.015 0.5" pos="0.5 0 0" quat="0.707107 0 -0.707107 0" type="capsule" contype="0" conaffinity="0" condim="1" solref="0.001" rgba="0.1 0.0533333 0.673333 1"/>
                <site name="S_4" pos="0 0 0" size="0.0135" rgba="0 0 0 0"/>
                <body name="B_4">
                  <geom size="0.0135" contype="0" conaffinity="0" mass="0" rgba="0.8 0.2 0.1 0.3"/>
                </body>
                <body name="Bmain_5" pos="1 0 0">
                  <joint name="J_5" pos="0 0 0" type="ball" actuatorfrclimited="false" damping="0.5"/>
                  <geom name="G5" size="0.015 0.5" pos="0.5 0 0" quat="0.707107 0 -0.707107 0" type="capsule" contype="0" conaffinity="0" condim="1" solref="0.001" rgba="0.1 0.0533333 0.673333 1"/>
                  <site name="S_5" pos="0 0 0" size="0.0135" rgba="0 0 0 0"/>
                  <body name="B_5">
                    <geom size="0.0135" contype="0" conaffinity="0" mass="0" rgba="0.8 0.2 0.1 0.3"/>
                  </body>
                  <body name="Bmain_6" pos="1 0 0">
                    <joint name="J_6" pos="0 0 0" type="ball" actuatorfrclimited="false" damping="0.5"/>
                    <geom name="G6" size="0.015 0.5" pos="0.5 0 0" quat="0.707107 0 -0.707107 0" type="capsule" contype="0" conaffinity="0" condim="1" solref="0.001" rgba="0.1 0.0533333 0.673333 1"/>
                    <site name="S_6" pos="0 0 0" size="0.0135" rgba="0 0 0 0"/>
                    <site name="twistcylx_7" pos="0 0 0.05" quat="0.707107 0 0 -0.707107" size="0.001 0.05" group="1" type="cylinder" rgba="0 0 1 0"/>
                    <site name="twistcyly_7" pos="0 0.05 0" quat="0.707107 -0.707107 0 0" size="0.001 0.05" group="1" type="cylinder" rgba="1 1 0 0"/>
                    <body name="B_6">
                      <geom size="0.0135" contype="0" conaffinity="0" mass="0" rgba="0.8 0.2 0.1 0.3"/>
                    </body>
                    <body name="Bmain_7" pos="1 0 0">
                      <joint name="J_7" pos="0 0 0" type="ball" actuatorfrclimited="false" damping="0.5"/>
                      <geom name="G7" size="0.015 0.5" pos="0.5 0 0" quat="0.707107 0 -0.707107 0" type="capsule" contype="0" conaffinity="0" condim="1" solref="0.001" rgba="0.1 0.0533333 0.673333 1"/>
                      <site name="S_7" pos="0 0 0" size="0.0135" rgba="0 0 0 0"/>
                      <body name="B_7">
                        <geom size="0.0135" contype="0" conaffinity="0" mass="0" rgba="0.8 0.2 0.1 0.3"/>
                      </body>
                      <body name="Bmain_8" pos="1 0 0">
                        <joint name="J_8" pos="0 0 0" type="ball" actuatorfrclimited="false" damping="0.5"/>
                        <geom name="G8" size="0.015 0.5" pos="0.5 0 0" quat="0.707107 0 -0.707107 0" type="capsule" contype="0" conaffinity="0" condim="1" solref="0.001" rgba="0.1 0.0533333 0.673333 1"/>
                        <site name="S_8" pos="0 0 0" size="0.0135" rgba="0 0 0 0"/>
                        <body name="B_8">
                          <geom size="0.0135" contype="0" conaffinity="0" mass="0" rgba="0.8 0.2 0.1 0.3"/>
                        </body>
                        <body name="Bmain_9" pos="1 0 0">
                          <joint name="J_9" pos="0 0 0" type="ball" actuatorfrclimited="false" damping="0.5"/>
                          <geom name="G9" size="0.015 0.5" pos="0.5 0 0" quat="0.707107 0 -0.707107 0" type="capsule" contype="0" conaffinity="0" condim="1" solref="0.001" rgba="0.1 0.0533333 0.673333 1"/>
                          <site name="S_9" pos="0 0 0" size="0.0135" rgba="0 0 0 0"/>
                          <body name="B_9">
                            <geom size="0.0135" contype="0" conaffinity="0" mass="0" rgba="0.8 0.2 0.1 0.3"/>
                          </body>
                          <body name="Bmain_10" pos="1 0 0">
                            <joint name="J_10" pos="0 0 0" type="ball" actuatorfrclimited="false" damping="0.5"/>
                            <geom name="G10" size="0.015 0.5" pos="0.5 0 0" quat="0.707107 0 -0.707107 0" type="capsule" contype="0" conaffinity="0" condim="1" solref="0.001" rgba="0.1 0.0533333 0.673333 1"/>
                            <site name="S_10" pos="0 0 0" size="0.0135" rgba="0 0 0 0"/>
                            <body name="B_10">
                              <geom size="0.0135" contype="0" conaffinity="0" mass="0" rgba="0.8 0.2 0.1 0.3"/>
                            </body>
                            <body name="Bmain_11" pos="1 0 0">
                              <joint name="J_11" pos="0 0 0" type="ball" actuatorfrclimited="false" damping="0.5"/>
                              <geom name="G11" size="0.015 0.5" pos="0.5 0 0" quat="0.707107 0 -0.707107 0" type="capsule" contype="0" conaffinity="0" condim="1" solref="0.001" rgba="0.1 0.0533333 0.673333 1"/>
                              <site name="S_11" pos="0 0 0" size="0.0135" rgba="0 0 0 0"/>
                              <body name="B_11">
                                <geom size="0.0135" contype="0" conaffinity="0" mass="0" rgba="0.8 0.2 0.1 0.3"/>
                              </body>
                              <body name="Bmain_last" pos="1 0 0">
                                <joint name="J_last" pos="0 0 0" type="ball" actuatorfrclimited="false" damping="0.5"/>
                                <geom name="G12" size="0.015 0.5" pos="0.5 0 0" quat="0.707107 0 -0.707107 0" type="capsule" contype="0" conaffinity="0" condim="1" solref="0.001" rgba="0.1 0.0533333 0.673333 1"/>
                                <site name="S_12" pos="0 0 0" size="0.0135" rgba="0 0 0 0"/>
                                <site name="twistcylx_13" pos="0 0 0.05" quat="0.707107 0 0 -0.707107" size="0.001 0.05" group="1" type="cylinder" rgba="0 0 1 0"/>
                                <site name="twistcyly_13" pos="0 0.05 0" quat="0.707107 -0.707107 0 0" size="0.001 0.05" group="1" type="cylinder" rgba="1 1 0 0"/>
                                <site name="S_last" pos="1 0 0" size="0.0135"/>
                                <body name="B_last">
                                  <geom size="0.0135" contype="0" conaffinity="0" mass="0" rgba="0.8 0.2 0.1 0.3"/>
                                </body>
                                <body name="B_last2" pos="1 0 0">
                                  <geom name="bl2_geom" size="0.0135" contype="0" conaffinity="0" mass="0" rgba="0.8 0.2 0.1 0.3"/>
                                </body>
                              </body>
                            </body>
                          </body>
                        </body>
                      </body>
                    </body>
                  </body>
                </body>
              </body>
            </body>
          </body>
        </body>
      </body>
    </body>
  </worldbody>

  <contact>
    <exclude body1="eef_body" body2="Bmain_first"/>
    <exclude body1="eef_body" body2="Bmain_11"/>
    <exclude body1="eef_body" body2="Bmain_last"/>
    <exclude body1="Bmain_first" body2="Bmain_1"/>
    <exclude body1="Bmain_first" body2="Bmain_11"/>
    <exclude body1="Bmain_first" body2="Bmain_last"/>
    <exclude body1="Bmain_1" body2="Bmain_2"/>
    <exclude body1="Bmain_1" body2="Bmain_last"/>
    <exclude body1="Bmain_2" body2="Bmain_3"/>
    <exclude body1="Bmain_3" body2="Bmain_4"/>
    <exclude body1="Bmain_4" body2="Bmain_5"/>
    <exclude body1="Bmain_5" body2="Bmain_6"/>
    <exclude body1="Bmain_6" body2="Bmain_7"/>
    <exclude body1="Bmain_7" body2="Bmain_8"/>
    <exclude body1="Bmain_8" body2="Bmain_9"/>
    <exclude body1="Bmain_9" body2="Bmain_10"/>
    <exclude body1="Bmain_10" body2="Bmain_11"/>
    <exclude body1="Bmain_11" body2="Bmain_last"/>
  </contact>

  <equality>
    <weld body1="B_last" body2="eef_body" anchor="0 0 0" relpose="1 0 0 0 0 -1 0" torquescale="1" solref="0.001"/>
    <weld body1="B_first" body2="eef_body2" anchor="0 0 0" relpose="0 0 0 0 0 -1 0" torquescale="1" solref="0.001"/>
  </equality>
</mujoco>
